Workbook
Name Beschriftung: OFFSET(#REF!,0,0,COUNTA(#REF!),-1)
Name Daten01: OFFSET(#REF!,0,0,COUNTA(#REF!),-1)
Name Daten02: OFFSET(#REF!,0,0,COUNTA(#REF!),-1)
Name Daten03: OFFSET(#REF!,0,0,COUNTA(#REF!),-1)
Name Daten04: OFFSET(#REF!,0,0,COUNTA(#REF!),-1)
Name Daten05: OFFSET(#REF!,0,0,COUNTA(#REF!),-1)
Name Daten06: OFFSET(#REF!,0,0,COUNTA(#REF!),-1)
Name Daten07: OFFSET(#REF!,0,0,COUNTA(#REF!),-1)
Name Daten08: OFFSET(#REF!,0,0,COUNTA(#REF!),-1)
Name Daten09: OFFSET(#REF!,0,0,COUNTA(#REF!),-1)
Name Daten10: OFFSET(#REF!,0,0,COUNTA(#REF!),-1)
Name Inputs: Tabelle13[#All]
Name Inputs: Tabelle13[#All]
Name Inputs: Tabelle13[#All]
Name Beschriftung: OFFSET(#REF!,0,0,COUNTA(#REF!),-1)
Name Daten01: OFFSET(#REF!,0,0,COUNTA(#REF!),-1)
Name Inputs: #REF!
Name Beschriftung: OFFSET(#REF!,0,0,COUNTA(#REF!),-1)
Name Daten01: OFFSET(#REF!,0,0,COUNTA(#REF!),-1)
Name Inputs: #REF!
Name Beschriftung: OFFSET(#REF!,0,0,COUNTA(#REF!),-1)
Name Daten01: OFFSET(#REF!,0,0,COUNTA(#REF!),-1)
Name Inputs: #REF!
Name Inputs: Tabelle13[#All]
Name Inputs: Tabelle13[#All]

Sheet 1. Readme
B1: Readme
B3: Version | C3: Description | D3: Comments/Changes
B4: V1.0 | C4: NNB reporting template, Version 1.0, April 29 2025 | D4: First version developed in a research project funded by the German Environment Agency (UBA) (Project No. (FKZ) 3722 63 2012)
B7: Notes:
B8: This template currently contains dummy values for N flows for the years 2018, 2020 and 2022 including corresponding uncertaintes (i.e. identical values for all N flows in a given year). Thus all figures and values in the output tables are only illustrative and do not reflect effective N inputs or outputs.
B11: Description
B12: The present template for national nitrogen budget (NNB) provides a predefined list of N flows that need to be quantified. Methods and information on available data sources are provided in the Annexes to the Guidance document on NNB. Once data for one or several years have been entered in the database table (table 2.), the subsequent sheets of this document allow for a visualization of the resulting nitrogen Budgets per pool and sub-pool, indluding also time series, that show the evolution of nitrogen wasted and losses of reactive nitrogen to the environment. Furthermore, the nitrogen use efficiency, i.e. the ratio between useful outputs of a pool (including recycling outputs) per total inputs to a pool are shown. The template also provides an interface table to the "NNB visualization tool" developped by the "UK Centre for Ecology & Hydrology" (see table 4 "Interface to NNB-R-Tool") and an additional interface table for importing the data to the Material Flow Analysis software STAN.
B15: Link to R visualization tool: | C15: Nitrogen budget visualisation tool (ceh.ac.uk)
B16: Link to STAN visualization template: | C16: https://www.clrtap-tfrn.org/sites/default/files/2025-04/NNB%20model%20STAN%20-%20master_V1.0.zmfa__0.zip
B17: Link to STAN software: | C17: https://www.stan2web.net/
B19: Structure of the template
B21: Cells that can be edited by users are formated as follows throughout the entire document:
B23: Tables to be edited
A24: Nr. | B24: Sheet | C24: Description | D24: Workflow & editing
A25: 2a | B25: Database N flows | C25: Database of N flows in which data on nitrogen flows and corresponding uncertainties can be entered. In addition, the year and country for which the N flow was quantified needs to be entered. It is recommended to document the data sources used for quantifying the flow, deviations from the methods proposed by the annexes and further comments, if necessary. To add N flows for additional years, the list of N flows for one year needs to be copied and pasted to the bottom end of the database sheet. | D25: Enter N-flow data in Columns N-T in the units and format described in row 2 -Value in kilotons of N -Uncertainty in % -Year -Data sources -Comment -Deviation from Guidance Document and justification -Country
A26: 2b | B26: Database Stock changes | C26: Optional: In cases where stock changes are quantified, corresponding data can be entered in this table for each sub-pool. | D26: Enter data on stock changes in Columns N-T in the units and format described in row 2 -Value in kilotons of N -Uncertainty in % -Year -Data sources -Comment -Deviation from Guidance Document and justification -Country
A27: 3.1.a | B27: Input Output Matrix per (sub-)pool | C27: Shows the matrix of total input and output N flows per pool and subpool The automatic color scheme of the background indicates high input-output values (dark green) and low input-output values (light green) | D27: Select input data (year, species) to be displayed by drop-down list
A28: 3.1.b | B28: Inputs and Outputs per pool | C28: Lists all N flows of a selected pool and shows total inputs and outputs including their uncertainty | D28: Select input data (year, pool) to be displayed by drop-down list
A29: 3.1.c | B29: N Budget | C29: Shows figures of N Budgets per pool and subpool, i.e. total inputs and total outputs | D29: Select input data (year, pool) to be displayed by drop-down list
A30: 3.2.a | B30: NUE | C30: Shows figures and tables of inputs and outputs of N flows on a country level and per pool and sub-pool. Provides nitrogen use efficiencies (NUE) on a country level and per pool and sub-pool. | D30: Select input data (year, pool) to be displayed by drop-down list
A31: 3.2.b | B31: NUE Agriculture | C31: Provides nitrogen use efficiencies (NUE) for the subpools of the pool agriculture, including a detailed list of relevant input and output N flows. | D31: Select input data (year) to be displayed by drop-down list
A32: 3.2.c | B32: NUE Whole economy | C32: Provides nitrogen use efficiencies (NUE) for the whole economy, including a detailed list of relevant input and output N flows. | D32: Select input data (year) to be displayed by drop-down list
A33: 3.3a | B33: Time series: N wasted | C33: Shows figures and tables with time series of: -N wasted including a comparison to the target "halving of N waste" | D33: Select input data (year, pool) to be displayed by drop-down list
A34: 3.3b | B34: Time series: Nr losses | C34: Shows figures and tables with time series of: -Losses of reactive N to the environment (pool FS, HY, AT) | D34: Select input data (year, pool) to be displayed by drop-down list
A35: 3.3c | B35: Time series N input and output | C35: Shows figures and tables with time series of: -total N inputs by pool and species | D35: Select input data (year, pool) to be displayed by drop-down list
A36: 4a | B36: Interface to NNB-R-Tool CSV | C36: Table to be exported to the NNB visualization tool developped by the "UK Centre for Ecology & Hydrology" in the programming language R. To import the data to the NNB visualization tool, this table needs to be saved as a CSV table and the CSV file can then be uploaded to the R visualization tool. | D36: Save table as CSV file Import table to R-Tool
A37: 4b | B37: Interface of NNB to STAN for visualisation of pool graphs | C37: Table to be exported to the STAN file to display the NNB with the pool graphs. To import the data to STAN, this table needs to be copied and pasted directly into the STAN data explorer (follow the steps on the right). | D37: {='4b Interface to NNB-STAN'!G3:G3}
B39: Background tables (no editing necessary)
B40: Sheet | C40: Description | D40: Workflow & editing
A41: 5a | B41: Definitions | C41: Definitions and abbreviations used in the database | D41: no editing required, includes only techincal information required for the drop down menues.
A42: 5b | B42: List of Inputs_Outputs | C42: Background tables for figures | D42: no editing required, includes only techincal information required for the linking of N flows to the respective sheets.
A43: 5c | B43: List of Flows | C43: Background tables for figures | D43: no editing required, includes only techincal information required for the linking of N flows to the respective sheets.
B46: Definitions of N species used in this document
B48: Abbreviation | C48: N species | D48: Chemical formula
B50: Reactive nitrogen Nr
B51: NOx | C51: Nitrogen oxides | D51: NOx (expressed as mass of NO2 by definition)
B52: NH3 | C52: Ammonia | D52: NH3
B53: N2O | C53: Nitrous oxide | D53: N2O
B54: Nmix | C54: Other reactive N species bound to materials (e.g. food, plastic, organic materials) or a mix of reactive N species (e.g. mixture of dissolved forms of nitrogen such as NO3-, NH4+, NO2-) | D54: -
B55: Inert nitrogen
...

Sheet 2a. Database N flows
B1: Flow | C1: Flow Code | D1: Pool-Out | E1: Subpool-Out | F1: Subpool-Out description | G1: Pool-In | H1: Subpool-In | I1: Subpool-In description | J1: Flow name | K1: STAN Flow name | L1: reactive/inactive | M1: Species | N1: Value | O1: Uncertainty | P1: Year | Q1: Data sources | R1: Comment | S1: Deviation from Guidance Document and justification | T1: Country | U1: Flow type
D2: - | E2: - | G2: - | H2: - | N2: kt N | O2: % | P2: - | Q2: text | R2: text | S2: text | T2: Country | U2: overViewType | V2: Uncertainty contribution
A3: Energy and fuels | B3: EF.EC-EF.IC | C3: EF.EC-EF.IC-Fuel for industry-Nmix | D3: EF | E3: EC | F3: =VLOOKUP(E3,'5.a Definitions'!E:F,2,FALSE) | G3: EF | H3: IC | I3: =VLOOKUP(H3,'5.a Definitions'!E:F,2,FALSE) | J3: Fuel for industry | K3: fuel for industry | L3: reactive | M3: Nmix | N3: nan | O3: 0.2 | P3: 2025 | Q3: no data | R3: not done | S3: text | T3: Norway | U3: useful output | V3: =(O3*N3)^2
B4: EF.EC-EF.TR | C4: EF.EC-EF.TR-Fuel for transport-Nmix | D4: EF | E4: EC | F4: =VLOOKUP(E4,'5.a Definitions'!E:F,2,FALSE) | G4: EF | H4: TR | I4: =VLOOKUP(H4,'5.a Definitions'!E:F,2,FALSE) | J4: Fuel for transport | K4: fuel for transport | L4: reactive | M4: Nmix | N4: nan | O4: 0.2 | P4: 2025 | Q4: no data | R4: not done | S4: text | T4: Norway | U4: useful output | V4: =(O4*N4)^2
B5: EF.EC-EF.OE | C5: EF.EC-EF.OE-Fuel for heating-Nmix | D5: EF | E5: EC | F5: =VLOOKUP(E5,'5.a Definitions'!E:F,2,FALSE) | G5: EF | H5: OE | I5: =VLOOKUP(H5,'5.a Definitions'!E:F,2,FALSE) | J5: Fuel for heating | K5: fuel for heating | L5: reactive | M5: Nmix | N5: nan | O5: 0.2 | P5: 2025 | Q5: no data | R5: not done | S5: text | T5: Norway | U5: useful output | V5: =(O5*N5)^2
B6: EF.EC-MP.OP | C6: EF.EC-MP.OP-Fuel used as feedstock-Nmix | D6: EF | E6: EC | F6: =VLOOKUP(E6,'5.a Definitions'!E:F,2,FALSE) | G6: MP | H6: OP | I6: =VLOOKUP(H6,'5.a Definitions'!E:F,2,FALSE) | J6: Fuel used as feedstock | K6: fuel used as feedstock | L6: reactive | M6: Nmix | N6: nan | O6: 0.2 | P6: 2025 | Q6: no data | R6: not done | S6: text | T6: Norway | U6: useful output | V6: =(O6*N6)^2
B7: EF.EC-AT.AT | C7: EF.EC-AT.AT-Emissions-NH3 | D7: EF | E7: EC | F7: =VLOOKUP(E7,'5.a Definitions'!E:F,2,FALSE) | G7: AT | H7: AT | I7: =VLOOKUP(H7,'5.a Definitions'!E:F,2,FALSE) | J7: Emissions | K7: energy conversion emissions | L7: reactive | M7: NH3 | N7: 0 | O7: 0.2 | P7: 2025 | Q7: no data | R7: not done | S7: text | T7: Norway | U7: N wasted | V7: =(O7*N7)^2
B8: EF.EC-AT.AT | C8: EF.EC-AT.AT-Emissions-NOx | D8: EF | E8: EC | F8: =VLOOKUP(E8,'5.a Definitions'!E:F,2,FALSE) | G8: AT | H8: AT | I8: =VLOOKUP(H8,'5.a Definitions'!E:F,2,FALSE) | J8: Emissions | K8: energy conversion emissions | L8: reactive | M8: NOx | N8: nan | O8: 0.2 | P8: 2025 | Q8: no data | R8: not done | S8: text | T8: Norway | U8: N wasted | V8: =(O8*N8)^2
B9: EF.EC-AT.AT | C9: EF.EC-AT.AT-Emissions-N2O | D9: EF | E9: EC | F9: =VLOOKUP(E9,'5.a Definitions'!E:F,2,FALSE) | G9: AT | H9: AT | I9: =VLOOKUP(H9,'5.a Definitions'!E:F,2,FALSE) | J9: Emissions | K9: energy conversion emissions | L9: reactive | M9: N2O | N9: nan | O9: 0.2 | P9: 2025 | Q9: no data | R9: not done | S9: text | T9: Norway | U9: N wasted | V9: =(O9*N9)^2
B10: EF.EC-AT.AT | C10: EF.EC-AT.AT-Emissions-N2 | D10: EF | E10: EC | F10: =VLOOKUP(E10,'5.a Definitions'!E:F,2,FALSE) | G10: AT | H10: AT | I10: =VLOOKUP(H10,'5.a Definitions'!E:F,2,FALSE) | J10: Emissions | K10: energy conversion emissions | L10: inert | M10: N2 | N10: 0 | O10: 10 | P10: 2025 | Q10: mass balance | R10: ok | S10: text | T10: Norway | U10: N wasted | V10: =(O10*N10)^2
B11: EF.EC-RW.RW | C11: EF.EC-RW.RW-Fuel export-Nmix | D11: EF | E11: EC | F11: =VLOOKUP(E11,'5.a Definitions'!E:F,2,FALSE) | G11: RW | H11: RW | I11: =VLOOKUP(H11,'5.a Definitions'!E:F,2,FALSE) | J11: Fuel export | K11: fuel export | L11: reactive | M11: Nmix | N11: nan | O11: 0.2 | P11: 2025 | Q11: no data | R11: not done | S11: text | T11: Norway | U11: useful output | V11: =(O11*N11)^2
B12: EF.IC-AT.AT | C12: EF.IC-AT.AT-Emissions-NH3 | D12: EF | E12: IC | F12: =VLOOKUP(E12,'5.a Definitions'!E:F,2,FALSE) | G12: AT | H12: AT | I12: =VLOOKUP(H12,'5.a Definitions'!E:F,2,FALSE) | J12: Emissions | K12: industrial emissions | L12: reactive | M12: NH3 | N12: nan | O12: 0.2 | P12: 2025 | Q12: no data | R12: not done | S12: text | T12: Norway | U12: N wasted | V12: =(O12*N12)^2
B13: EF.IC-AT.AT | C13: EF.IC-AT.AT-Emissions-NOx | D13: EF | E13: IC | F13: =VLOOKUP(E13,'5.a Definitions'!E:F,2,FALSE) | G13: AT | H13: AT | I13: =VLOOKUP(H13,'5.a Definitions'!E:F,2,FALSE) | J13: Emissions | K13: industrial emissions | L13: reactive | M13: NOx | N13: nan | O13: 0.2 | P13: 2025 | Q13: no data | R13: not done | S13: text | T13: Norway | U13: N wasted | V13: =(O13*N13)^2
B14: EF.IC-AT.AT | C14: EF.IC-AT.AT-Emissions-N2O | D14: EF | E14: IC | F14: =VLOOKUP(E14,'5.a Definitions'!E:F,2,FALSE) | G14: AT | H14: AT | I14: =VLOOKUP(H14,'5.a Definitions'!E:F,2,FALSE) | J14: Emissions | K14: industrial emissions | L14: reactive | M14: N2O | N14: nan | O14: 0.2 | P14: 2025 | Q14: no data | R14: not done | S14: text | T14: Norway | U14: N wasted | V14: =(O14*N14)^2
B15: EF.TR-AT.AT | C15: EF.TR-AT.AT-Emissions-NH3 | D15: EF | E15: TR | F15: =VLOOKUP(E15,'5.a Definitions'!E:F,2,FALSE) | G15: AT | H15: AT | I15: =VLOOKUP(H15,'5.a Definitions'!E:F,2,FALSE) | J15: Emissions | K15: transport emissions | L15: reactive | M15: NH3 | N15: nan | O15: 0.2 | P15: 2025 | Q15: no data | R15: not done | S15: text | T15: Norway | U15: N wasted | V15: =(O15*N15)^2
B16: EF.TR-AT.AT | C16: EF.TR-AT.AT-Emissions-NOx | D16: EF | E16: TR | F16: =VLOOKUP(E16,'5.a Definitions'!E:F,2,FALSE) | G16: AT | H16: AT | I16: =VLOOKUP(H16,'5.a Definitions'!E:F,2,FALSE) | J16: Emissions | K16: transport emissions | L16: reactive | M16: NOx | N16: nan | O16: 0.2 | P16: 2025 | Q16: no data | R16: not done | S16: text | T16: Norway | U16: N wasted | V16: =(O16*N16)^2
B17: EF.TR-AT.AT | C17: EF.TR-AT.AT-Emissions-N2O | D17: EF | E17: TR | F17: =VLOOKUP(E17,'5.a Definitions'!E:F,2,FALSE) | G17: AT | H17: AT | I17: =VLOOKUP(H17,'5.a Definitions'!E:F,2,FALSE) | J17: Emissions | K17: transport emissions | L17: reactive | M17: N2O | N17: nan | O17: 0.2 | P17: 2025 | Q17: no data | R17: not done | S17: text | T17: Norway | U17: N wasted | V17: =(O17*N17)^2
B18: EF.TR-AT.AT | C18: EF.TR-AT.AT-Emissions-N2 | D18: EF | E18: TR | F18: =VLOOKUP(E18,'5.a Definitions'!E:F,2,FALSE) | G18: AT | H18: AT | I18: =VLOOKUP(H18,'5.a Definitions'!E:F,2,FALSE) | J18: Emissions | K18: transport emissions | L18: inert | M18: N2 | N18: 0 | O18: 0.2 | P18: 2025 | Q18: no data | R18: not done | S18: text | T18: Norway | U18: N wasted | V18: =(O18*N18)^2
B19: EF.TR-RW.RW | C19: EF.TR-RW.RW-Export of transport fuels-Nmix | D19: EF | E19: TR | F19: =VLOOKUP(E19,'5.a Definitions'!E:F,2,FALSE) | G19: RW | H19: RW | I19: =VLOOKUP(H19,'5.a Definitions'!E:F,2,FALSE) | J19: Export of transport fuels | K19: export of transport fuel | L19: reactive | M19: Nmix | N19: nan | O19: 0.2 | P19: 2025 | Q19: no data | R19: not done | S19: text | T19: Norway | U19: useful output | V19: =(O19*N19)^2
B20: EF.OE-AT.AT | C20: EF.OE-AT.AT-Emissions-NH3 | D20: EF | E20: OE | F20: =VLOOKUP(E20,'5.a Definitions'!E:F,2,FALSE) | G20: AT | H20: AT | I20: =VLOOKUP(H20,'5.a Definitions'!E:F,2,FALSE) | J20: Emissions | K20: other fuels emissions | L20: reactive | M20: NH3 | N20: nan | O20: 0.2 | P20: 2025 | Q20: no data | R20: not done | S20: text | T20: Norway | U20: N wasted | V20: =(O20*N20)^2
B21: EF.OE-AT.AT | C21: EF.OE-AT.AT-Emissions-NOx | D21: EF | E21: OE | F21: =VLOOKUP(E21,'5.a Definitions'!E:F,2,FALSE) | G21: AT | H21: AT | I21: =VLOOKUP(H21,'5.a Definitions'!E:F,2,FALSE) | J21: Emissions | K21: other fuels emissions | L21: reactive | M21: NOx | N21: nan | O21: 0.2 | P21: 2025 | Q21: no data | R21: not done | S21: text | T21: Norway | U21: N wasted | V21: =(O21*N21)^2
B22: EF.OE-AT.AT | C22: EF.OE-AT.AT-Emissions-N2O | D22: EF | E22: OE | F22: =VLOOKUP(E22,'5.a Definitions'!E:F,2,FALSE) | G22: AT | H22: AT | I22: =VLOOKUP(H22,'5.a Definitions'!E:F,2,FALSE) | J22: Emissions | K22: other fuels emissions | L22: reactive | M22: N2O | N22: nan | O22: 0.2 | P22: 2025 | Q22: no data | R22: not done | S22: text | T22: Norway | U22: N wasted | V22: =(O22*N22)^2
B23: EF.OE-AT.AT | C23: EF.OE-AT.AT-Emissions-N2 | D23: EF | E23: OE | F23: =VLOOKUP(E23,'5.a Definitions'!E:F,2,FALSE) | G23: AT | H23: AT | I23: =VLOOKUP(H23,'5.a Definitions'!E:F,2,FALSE) | J23: Emissions | K23: other fuels emissions | L23: inert | M23: N2 | N23: 0 | O23: 0.2 | P23: 2025 | Q23: no data | R23: not done | S23: text | T23: Norway | U23: N wasted | V23: =(O23*N23)^2
A24: Materials and products | B24: MP.FP-AG.SM | C24: MP.FP-AG.SM-Seeds and planting material -Nmix | D24: MP | E24: FP | F24: =VLOOKUP(E24,'5.a Definitions'!E:F,2,FALSE) | G24: AG | H24: SM | I24: =VLOOKUP(H24,'5.a Definitions'!E:F,2,FALSE) | J24: Seeds and planting material | K24: seeds and planting material | L24: reactive | M24: Nmix | N24: 1.2237959 | O24: 0.31814404 | P24: 2025 | Q24: NIBIO Totalkalkylen | R24: ok | S24: text | T24: Norway | U24: useful output | V24: =(O24*N24)^2
B25: MP.FP-AG.MM | C25: MP.FP-AG.MM-Farm animal feed-Nmix | D25: MP | E25: FP | F25: =VLOOKUP(E25,'5.a Definitions'!E:F,2,FALSE) | G25: AG | H25: MM | I25: =VLOOKUP(H25,'5.a Definitions'!E:F,2,FALSE) | J25: Farm animal feed | K25: farm animal feed | L25: reactive | M25: Nmix | N25: nan | O25: 0.2 | P25: 2025 | Q25: no data | R25: not done | S25: text | T25: Norway | U25: useful output | V25: =(O25*N25)^2
B26: MP.FP-PR.SO | C26: MP.FP-PR.SO-Food industry waste-Nmix | D26: MP | E26: FP | F26: =VLOOKUP(E26,'5.a Definitions'!E:F,2,FALSE) | G26: PR | H26: SO | I26: =VLOOKUP(H26,'5.a Definitions'!E:F,2,FALSE) | J26: Food industry waste | K26: food industry waste | L26: reactive | M26: Nmix | N26: nan | O26: 0.2 | P26: 2025 | Q26: no data | R26: not done | S26: text | T26: Norway | U26: N wasted | V26: =(O26*N26)^2
B27: MP.FP-PR.WW | C27: MP.FP-PR.WW-Food industry wastewater-Nmix | D27: MP | E27: FP | F27: =VLOOKUP(E27,'5.a Definitions'!E:F,2,FALSE) | G27: PR | H27: WW | I27: =VLOOKUP(H27,'5.a Definitions'!E:F,2,FALSE) | J27: Food industry wastewater | K27: food industry wastewater | L27: reactive | M27: Nmix | N27: nan | O27: 0.2 | P27: 2025 | Q27: no data | R27: not done | S27: text | T27: Norway | U27: N wasted | V27: =(O27*N27)^2
B28: MP.FP-HS.HS | C28: MP.FP-HS.HS-Food products-Nmix | D28: MP | E28: FP | F28: =VLOOKUP(E28,'5.a Definitions'!E:F,2,FALSE) | G28: HS | H28: HS | I28: =VLOOKUP(H28,'5.a Definitions'!E:F,2,FALSE) | J28: Food products | K28: food products | L28: reactive | M28: Nmix | N28: 30.867683 | O28: 0.1853374 | P28: 2025 | Q28: SSB | R28: ok | S28: text | T28: Norway | U28: useful output | V28: =(O28*N28)^2
B29: MP.FP-HY.SW | C29: MP.FP-HY.SW-Untreated wastewater-Nmix | D29: MP | E29: FP | F29: =VLOOKUP(E29,'5.a Definitions'!E:F,2,FALSE) | G29: HY | H29: SW | I29: =VLOOKUP(H29,'5.a Definitions'!E:F,2,FALSE) | J29: Untreated wastewater | K29: food industry untreated wastewater | L29: reactive | M29: Nmix | N29: nan | O29: 0.2 | P29: 2025 | Q29: no data | R29: not done | S29: text | T29: Norway | U29: N wasted | V29: =(O29*N29)^2
B30: MP.FP-HY.AC | C30: MP.FP-HY.AC-Feed to freshwater aquaculture-Nmix | D30: MP | E30: FP | F30: =VLOOKUP(E30,'5.a Definitions'!E:F,2,FALSE) | G30: HY | H30: AC | I30: =VLOOKUP(H30,'5.a Definitions'!E:F,2,FALSE) | J30: Feed to freshwater aquaculture | K30: feed to freshwater aquaculture | L30: reactive | M30: Nmix | N30: 0 | O30: 0.2 | P30: 2025 | Q30: no production | R30: ok | S30: text | T30: Norway | U30: useful output | V30: =(O30*N30)^2
B31: MP.FP-HY.AC | C31: MP.FP-HY.AC-Feed to coastal aquaculture-Nmix | D31: MP | E31: FP | F31: =VLOOKUP(E31,'5.a Definitions'!E:F,2,FALSE) | G31: HY | H31: AC | I31: =VLOOKUP(H31,'5.a Definitions'!E:F,2,FALSE) | J31: Feed to coastal aquaculture | K31: feed to coastal aquaculture | L31: reactive | M31: Nmix | N31: nan | O31: 0.2 | P31: 2025 | Q31: no data | R31: not done | S31: text | T31: Norway | U31: useful output | V31: =(O31*N31)^2
B32: MP.FP-RW.RW | C32: MP.FP-RW.RW-Food export-Nmix | D32: MP | E32: FP | F32: =VLOOKUP(E32,'5.a Definitions'!E:F,2,FALSE) | G32: RW | H32: RW | I32: =VLOOKUP(H32,'5.a Definitions'!E:F,2,FALSE) | J32: Food export | K32: food export | L32: reactive | M32: Nmix | N32: nan | O32: 0.2 | P32: 2025 | Q32: no data | R32: not done | S32: text | T32: Norway | U32: useful output | V32: =(O32*N32)^2
B33: MP.FP-RW.RW | C33: MP.FP-RW.RW-Feed export-Nmix | D33: MP | E33: FP | F33: =VLOOKUP(E33,'5.a Definitions'!E:F,2,FALSE) | G33: RW | H33: RW | I33: =VLOOKUP(H33,'5.a Definitions'!E:F,2,FALSE) | J33: Feed export | K33: feed export | L33: reactive | M33: Nmix | N33: nan | O33: 0.2 | P33: 2025 | Q33: no data | R33: not done | S33: text | T33: Norway | U33: useful output | V33: =(O33*N33)^2
B34: MP.OP-AG.SM | C34: MP.OP-AG.SM-Mineral fertilizer-Nmix | D34: MP | E34: OP | F34: =VLOOKUP(E34,'5.a Definitions'!E:F,2,FALSE) | G34: AG | H34: SM | I34: =VLOOKUP(H34,'5.a Definitions'!E:F,2,FALSE) | J34: Mineral fertilizer | K34: mineral fertilizer to agriculture | L34: reactive | M34: Nmix | N34: nan | O34: 0.2 | P34: 2025 | Q34: no data | R34: not done | S34: text | T34: Norway | U34: useful output | V34: =(O33*N33)^2
B35: MP.OP-EF.IC | C35: MP.OP-EF.IC-Industrial waste fuels-Nmix | D35: MP | E35: OP | F35: =VLOOKUP(E35,'5.a Definitions'!E:F,2,FALSE) | G35: EF | H35: IC | I35: =VLOOKUP(H35,'5.a Definitions'!E:F,2,FALSE) | J35: Industrial waste fuel | K35: industrial waste fuel | L35: reactive | M35: Nmix | N35: nan | O35: 0.2 | P35: 2025 | Q35: no data | R35: not done | S35: text | T35: Norway | U35: useful output | V35: =(O35*N35)^2
B36: MP.OP-PR.SO | C36: MP.OP-PR.SO-Other industry waste-Nmix | D36: MP | E36: OP | F36: =VLOOKUP(E36,'5.a Definitions'!E:F,2,FALSE) | G36: PR | H36: SO | I36: =VLOOKUP(H36,'5.a Definitions'!E:F,2,FALSE) | J36: Other industry waste | K36: other industry waste | L36: reactive | M36: Nmix | N36: nan | O36: 0.2 | P36: 2025 | Q36: no data | R36: not done | S36: text | T36: Norway | U36: N wasted | V36: =(O34*N34)^2
B37: MP.OP-PR.WW | C37: MP.OP-PR.WW-Other industry wastewater-Nmix | D37: MP | E37: OP | F37: =VLOOKUP(E37,'5.a Definitions'!E:F,2,FALSE) | G37: PR | H37: WW | I37: =VLOOKUP(H37,'5.a Definitions'!E:F,2,FALSE) | J37: Other industry wastewater | K37: other industry wastewater | L37: reactive | M37: Nmix | N37: nan | O37: 0.2 | P37: 2025 | Q37: no data | R37: not done | S37: text | T37: Norway | U37: N wasted | V37: =(O35*N35)^2
B38: MP.OP-HS.HS | C38: MP.OP-HS.HS-Mineral fertilizer-Nmix | D38: MP | E38: OP | F38: =VLOOKUP(E38,'5.a Definitions'!E:F,2,FALSE) | G38: HS | H38: HS | I38: =VLOOKUP(H38,'5.a Definitions'!E:F,2,FALSE) | J38: Mineral fertilizer | K38: mineral fertilizer to settlements | L38: reactive | M38: Nmix | N38: nan | O38: 0.2 | P38: 2025 | Q38: no data | R38: not done | S38: text | T38: Norway | U38: useful output | V38: =(O36*N36)^2
B39: MP.OP-HS.HS | C39: MP.OP-HS.HS-Consumer goods-Nmix | D39: MP | E39: OP | F39: =VLOOKUP(E39,'5.a Definitions'!E:F,2,FALSE) | G39: HS | H39: HS | I39: =VLOOKUP(H39,'5.a Definitions'!E:F,2,FALSE) | J39: Consumer goods | K39: consumer goods | L39: reactive | M39: Nmix | N39: nan | O39: 0.3 | P39: 2025 | Q39: entries missing for mass balance | R39: in progress: only 0/6 inflows and 0/5 outflows | S39: text | T39: Norway | U39: useful output | V39: =(O37*N37)^2
B40: MP.OP-AT.AT | C40: MP.OP-AT.AT-Emissions-NH3 | D40: MP | E40: OP | F40: =VLOOKUP(E40,'5.a Definitions'!E:F,2,FALSE) | G40: AT | H40: AT | I40: =VLOOKUP(H40,'5.a Definitions'!E:F,2,FALSE) | J40: Emissions | K40: process emissions | L40: reactive | M40: NH3 | N40: nan | O40: 0.2 | P40: 2025 | Q40: no data | R40: not done | S40: text | T40: Norway | U40: N wasted | V40: =(O38*N38)^2
...

Sheet 2b. Database Stock changes
B1: Flow | C1: Flow Code | D1: Pool-Out | E1: Subpool-Out | F1: Subpool-Out description | G1: Pool-In | H1: Subpool-In | I1: Subpool-In description | J1: Flow name | K1: STAN Flow name | L1: reactive/inactive | M1: Species | N1: Value | O1: Uncertainty | P1: Year | Q1: Data sources | R1: Comment | S1: Deviation from Guidance Document and justification | T1: Country | U1: Flow type
D2: - | E2: - | G2: - | H2: - | N2: kt N | O2: % | P2: - | Q2: text | R2: text | S2: text | T2: Country | U2: overViewType | V2: Uncertainty contribution
A3: Energy and fuels | B3: =D3&"."&E3&"-"&G3&"."&H3 | C3: =B3&"-"&J3&"-"&M3 | D3: EF | E3: EC | F3: =VLOOKUP(E3,'5.a Definitions'!E:F,2,FALSE) | G3: EF | H3: EC | I3: =VLOOKUP(H3,'5.a Definitions'!E:F,2,FALSE) | J3: Stock change | K3: =J3 | L3: reactive | M3: Nmix | N3: 1 | O3: 0.2 | P3: 2018 | Q3: text | R3: text | S3: text | T3: Germany | U3: - | V3: =(O3*N3)^2
B4: =D4&"."&E4&"-"&G4&"."&H4 | C4: =B4&"-"&J4&"-"&M4 | D4: EF | E4: IC | F4: =VLOOKUP(E4,'5.a Definitions'!E:F,2,FALSE) | G4: EF | H4: IC | I4: =VLOOKUP(H4,'5.a Definitions'!E:F,2,FALSE) | J4: Stock change | K4: =J4 | L4: reactive | M4: Nmix | N4: 1 | O4: 0.2 | P4: 2018 | Q4: text | R4: text | S4: text | T4: Germany | U4: - | V4: =(O4*N4)^2
B5: =D5&"."&E5&"-"&G5&"."&H5 | C5: =B5&"-"&J5&"-"&M5 | D5: EF | E5: TR | F5: =VLOOKUP(E5,'5.a Definitions'!E:F,2,FALSE) | G5: EF | H5: TR | I5: =VLOOKUP(H5,'5.a Definitions'!E:F,2,FALSE) | J5: Stock change | K5: =J5 | L5: reactive | M5: Nmix | N5: 1 | O5: 0.2 | P5: 2018 | Q5: text | R5: text | S5: text | T5: Germany | U5: - | V5: =(O5*N5)^2
B6: =D6&"."&E6&"-"&G6&"."&H6 | C6: =B6&"-"&J6&"-"&M6 | D6: EF | E6: OE | F6: =VLOOKUP(E6,'5.a Definitions'!E:F,2,FALSE) | G6: EF | H6: OE | I6: =VLOOKUP(H6,'5.a Definitions'!E:F,2,FALSE) | J6: Stock change | K6: =J6 | L6: reactive | M6: Nmix | N6: 1 | O6: 0.2 | P6: 2018 | Q6: text | R6: text | S6: text | T6: Germany | U6: - | V6: =(O6*N6)^2
A7: Materials and products | B7: =D7&"."&E7&"-"&G7&"."&H7 | C7: =B7&"-"&J7&"-"&M7 | D7: MP | E7: FP | F7: =VLOOKUP(E7,'5.a Definitions'!E:F,2,FALSE) | G7: MP | H7: FP | I7: =VLOOKUP(H7,'5.a Definitions'!E:F,2,FALSE) | J7: Stock change | K7: =J7 | L7: reactive | M7: Nmix | N7: 1 | O7: 0.2 | P7: 2018 | Q7: text | R7: text | S7: text | T7: Germany | U7: - | V7: =(O7*N7)^2
B8: =D8&"."&E8&"-"&G8&"."&H8 | C8: =B8&"-"&J8&"-"&M8 | D8: MP | E8: OP | F8: =VLOOKUP(E8,'5.a Definitions'!E:F,2,FALSE) | G8: MP | H8: OP | I8: =VLOOKUP(H8,'5.a Definitions'!E:F,2,FALSE) | J8: Stock change | K8: =J8 | L8: reactive | M8: Nmix | N8: 1 | O8: 0.2 | P8: 2018 | Q8: text | R8: text | S8: text | T8: Germany | U8: - | V8: =(O8*N8)^2
A9: Agriculture | B9: =D9&"."&E9&"-"&G9&"."&H9 | C9: =B9&"-"&J9&"-"&M9 | D9: AG | E9: MM | F9: =VLOOKUP(E9,'5.a Definitions'!E:F,2,FALSE) | G9: AG | H9: MM | I9: =VLOOKUP(H9,'5.a Definitions'!E:F,2,FALSE) | J9: Stock change | K9: =J9 | L9: reactive | M9: Nmix | N9: 1 | O9: 0.2 | P9: 2018 | Q9: text | R9: text | S9: text | T9: Germany | U9: - | V9: =(O9*N9)^2
B10: =D10&"."&E10&"-"&G10&"."&H10 | C10: =B10&"-"&J10&"-"&M10 | D10: AG | E10: SM | F10: =VLOOKUP(E10,'5.a Definitions'!E:F,2,FALSE) | G10: AG | H10: SM | I10: =VLOOKUP(H10,'5.a Definitions'!E:F,2,FALSE) | J10: Stock change | K10: =J10 | L10: reactive | M10: Nmix | N10: 1 | O10: 0.2 | P10: 2018 | Q10: text | R10: text | S10: text | T10: Germany | U10: - | V10: =(O10*N10)^2
B11: =D11&"."&E11&"-"&G11&"."&H11 | C11: =B11&"-"&J11&"-"&M11 | D11: AG | E11: BC | F11: =VLOOKUP(E11,'5.a Definitions'!E:F,2,FALSE) | G11: AG | H11: BC | I11: =VLOOKUP(H11,'5.a Definitions'!E:F,2,FALSE) | J11: Stock change | K11: =J11 | L11: reactive | M11: Nmix | N11: 1 | O11: 0.2 | P11: 2018 | Q11: text | R11: text | S11: text | T11: Germany | U11: - | V11: =(O11*N11)^2
A12: Forests and Semi-natural vegetation | B12: =D12&"."&E12&"-"&G12&"."&H12 | C12: =B12&"-"&J12&"-"&M12 | D12: FS | E12: FO | F12: =VLOOKUP(E12,'5.a Definitions'!E:F,2,FALSE) | G12: FS | H12: FO | I12: =VLOOKUP(H12,'5.a Definitions'!E:F,2,FALSE) | J12: Stock change | K12: =J12 | L12: reactive | M12: Nmix | N12: 1 | O12: 0.2 | P12: 2018 | Q12: text | R12: text | S12: text | T12: Germany | U12: - | V12: =(O12*N12)^2
B13: =D13&"."&E13&"-"&G13&"."&H13 | C13: =B13&"-"&J13&"-"&M13 | D13: FS | E13: OL | F13: =VLOOKUP(E13,'5.a Definitions'!E:F,2,FALSE) | G13: FS | H13: OL | I13: =VLOOKUP(H13,'5.a Definitions'!E:F,2,FALSE) | J13: Stock change | K13: =J13 | L13: reactive | M13: Nmix | N13: 1 | O13: 0.2 | P13: 2018 | Q13: text | R13: text | S13: text | T13: Germany | U13: - | V13: =(O13*N13)^2
B14: =D14&"."&E14&"-"&G14&"."&H14 | C14: =B14&"-"&J14&"-"&M14 | D14: FS | E14: WL | F14: =VLOOKUP(E14,'5.a Definitions'!E:F,2,FALSE) | G14: FS | H14: WL | I14: =VLOOKUP(H14,'5.a Definitions'!E:F,2,FALSE) | J14: Stock change | K14: =J14 | L14: reactive | M14: Nmix | N14: 1 | O14: 0.2 | P14: 2018 | Q14: text | R14: text | S14: text | T14: Germany | U14: - | V14: =(O14*N14)^2
A15: Processing of residues | B15: =D15&"."&E15&"-"&G15&"."&H15 | C15: =B15&"-"&J15&"-"&M15 | D15: PR | E15: SO | F15: =VLOOKUP(E15,'5.a Definitions'!E:F,2,FALSE) | G15: PR | H15: SO | I15: =VLOOKUP(H15,'5.a Definitions'!E:F,2,FALSE) | J15: Stock change | K15: =J15 | L15: reactive | M15: Nmix | N15: 1 | O15: 0.2 | P15: 2018 | Q15: text | R15: text | S15: text | T15: Germany | U15: - | V15: =(O15*N15)^2
B16: =D16&"."&E16&"-"&G16&"."&H16 | C16: =B16&"-"&J16&"-"&M16 | D16: PR | E16: WW | F16: =VLOOKUP(E16,'5.a Definitions'!E:F,2,FALSE) | G16: PR | H16: WW | I16: =VLOOKUP(H16,'5.a Definitions'!E:F,2,FALSE) | J16: Stock change | K16: =J16 | L16: reactive | M16: Nmix | N16: 1 | O16: 0.2 | P16: 2018 | Q16: text | R16: text | S16: text | T16: Germany | U16: - | V16: =(O16*N16)^2
A17: Humans and settlements | B17: =D17&"."&E17&"-"&G17&"."&H17 | C17: =B17&"-"&J17&"-"&M17 | D17: HS | E17: HS | F17: =VLOOKUP(E17,'5.a Definitions'!E:F,2,FALSE) | G17: HS | H17: HS | I17: =VLOOKUP(H17,'5.a Definitions'!E:F,2,FALSE) | J17: Stock change | K17: =J17 | L17: reactive | M17: Nmix | N17: 1 | O17: 0.2 | P17: 2018 | Q17: text | R17: text | S17: text | T17: Germany | U17: - | V17: =(O17*N17)^2
A18: Atmosphere | B18: =D18&"."&E18&"-"&G18&"."&H18 | C18: =B18&"-"&J18&"-"&M18 | D18: AT | E18: AT | F18: =VLOOKUP(E18,'5.a Definitions'!E:F,2,FALSE) | G18: AT | H18: AT | I18: =VLOOKUP(H18,'5.a Definitions'!E:F,2,FALSE) | J18: Stock change | K18: =J18 | L18: reactive | M18: Nmix | N18: 1 | O18: 0.2 | P18: 2018 | Q18: text | R18: text | S18: text | T18: Germany | U18: - | V18: =(O18*N18)^2
B19: =D19&"."&E19&"-"&G19&"."&H19 | C19: =B19&"-"&J19&"-"&M19 | D19: AT | E19: AT | F19: =VLOOKUP(E19,'5.a Definitions'!E:F,2,FALSE) | G19: AT | H19: AT | I19: =VLOOKUP(H19,'5.a Definitions'!E:F,2,FALSE) | J19: Stock change | K19: =J19 | L19: reactive | M19: Nmix | N19: 1 | O19: 0.2 | P19: 2018 | Q19: text | R19: text | S19: text | T19: Germany | U19: - | V19: =(O19*N19)^2
A20: Hydrosphere | B20: =D20&"."&E20&"-"&G20&"."&H20 | C20: =B20&"-"&J20&"-"&M20 | D20: HY | E20: GW | F20: =VLOOKUP(E20,'5.a Definitions'!E:F,2,FALSE) | G20: HY | H20: GW | I20: =VLOOKUP(H20,'5.a Definitions'!E:F,2,FALSE) | J20: Stock change | K20: =J20 | L20: reactive | M20: Nmix | N20: 1 | O20: 0.2 | P20: 2018 | Q20: text | R20: text | S20: text | T20: Germany | U20: - | V20: =(O20*N20)^2
B21: =D21&"."&E21&"-"&G21&"."&H21 | C21: =B21&"-"&J21&"-"&M21 | D21: HY | E21: SW | F21: =VLOOKUP(E21,'5.a Definitions'!E:F,2,FALSE) | G21: HY | H21: SW | I21: =VLOOKUP(H21,'5.a Definitions'!E:F,2,FALSE) | J21: Stock change | K21: =J21 | L21: reactive | M21: Nmix | N21: 1 | O21: 0.2 | P21: 2018 | Q21: text | R21: text | S21: text | T21: Germany | U21: - | V21: =(O21*N21)^2
B22: =D22&"."&E22&"-"&G22&"."&H22 | C22: =B22&"-"&J22&"-"&M22 | D22: HY | E22: CW | F22: =VLOOKUP(E22,'5.a Definitions'!E:F,2,FALSE) | G22: HY | H22: CW | I22: =VLOOKUP(H22,'5.a Definitions'!E:F,2,FALSE) | J22: Stock change | K22: =J22 | L22: reactive | M22: Nmix | N22: 1 | O22: 0.2 | P22: 2018 | Q22: text | R22: text | S22: text | T22: Germany | U22: - | V22: =(O22*N22)^2
B23: =D23&"."&E23&"-"&G23&"."&H23 | C23: =B23&"-"&J23&"-"&M23 | D23: HY | E23: AC | F23: =VLOOKUP(E23,'5.a Definitions'!E:F,2,FALSE) | G23: HY | H23: AC | I23: =VLOOKUP(H23,'5.a Definitions'!E:F,2,FALSE) | J23: Stock change | K23: =J23 | L23: reactive | M23: Nmix | N23: 1 | O23: 0.2 | P23: 2018 | Q23: text | R23: text | S23: text | T23: Germany | U23: - | V23: =(O23*N23)^2
A25: Energy and fuels | B25: =D25&"."&E25&"-"&G25&"."&H25 | C25: =B25&"-"&J25&"-"&M25 | D25: EF | E25: EC | F25: =VLOOKUP(E25,'5.a Definitions'!E:F,2,FALSE) | G25: EF | H25: EC | I25: =VLOOKUP(H25,'5.a Definitions'!E:F,2,FALSE) | J25: Stock change | K25: =J25 | L25: reactive | M25: Nmix | N25: 1 | O25: 0.2 | P25: 2020 | Q25: text | R25: text | S25: text | T25: Germany | U25: - | V25: =(O25*N25)^2
B26: =D26&"."&E26&"-"&G26&"."&H26 | C26: =B26&"-"&J26&"-"&M26 | D26: EF | E26: IC | F26: =VLOOKUP(E26,'5.a Definitions'!E:F,2,FALSE) | G26: EF | H26: IC | I26: =VLOOKUP(H26,'5.a Definitions'!E:F,2,FALSE) | J26: Stock change | K26: =J26 | L26: reactive | M26: Nmix | N26: 1 | O26: 0.2 | P26: 2020 | Q26: text | R26: text | S26: text | T26: Germany | U26: - | V26: =(O26*N26)^2
B27: =D27&"."&E27&"-"&G27&"."&H27 | C27: =B27&"-"&J27&"-"&M27 | D27: EF | E27: TR | F27: =VLOOKUP(E27,'5.a Definitions'!E:F,2,FALSE) | G27: EF | H27: TR | I27: =VLOOKUP(H27,'5.a Definitions'!E:F,2,FALSE) | J27: Stock change | K27: =J27 | L27: reactive | M27: Nmix | N27: 1 | O27: 0.2 | P27: 2020 | Q27: text | R27: text | S27: text | T27: Germany | U27: - | V27: =(O27*N27)^2
B28: =D28&"."&E28&"-"&G28&"."&H28 | C28: =B28&"-"&J28&"-"&M28 | D28: EF | E28: OE | F28: =VLOOKUP(E28,'5.a Definitions'!E:F,2,FALSE) | G28: EF | H28: OE | I28: =VLOOKUP(H28,'5.a Definitions'!E:F,2,FALSE) | J28: Stock change | K28: =J28 | L28: reactive | M28: Nmix | N28: 1 | O28: 0.2 | P28: 2020 | Q28: text | R28: text | S28: text | T28: Germany | U28: - | V28: =(O28*N28)^2
A29: Materials and products | B29: =D29&"."&E29&"-"&G29&"."&H29 | C29: =B29&"-"&J29&"-"&M29 | D29: MP | E29: FP | F29: =VLOOKUP(E29,'5.a Definitions'!E:F,2,FALSE) | G29: MP | H29: FP | I29: =VLOOKUP(H29,'5.a Definitions'!E:F,2,FALSE) | J29: Stock change | K29: =J29 | L29: reactive | M29: Nmix | N29: 1 | O29: 0.2 | P29: 2020 | Q29: text | R29: text | S29: text | T29: Germany | U29: - | V29: =(O29*N29)^2
B30: =D30&"."&E30&"-"&G30&"."&H30 | C30: =B30&"-"&J30&"-"&M30 | D30: MP | E30: OP | F30: =VLOOKUP(E30,'5.a Definitions'!E:F,2,FALSE) | G30: MP | H30: OP | I30: =VLOOKUP(H30,'5.a Definitions'!E:F,2,FALSE) | J30: Stock change | K30: =J30 | L30: reactive | M30: Nmix | N30: 1 | O30: 0.2 | P30: 2020 | Q30: text | R30: text | S30: text | T30: Germany | U30: - | V30: =(O30*N30)^2
A31: Agriculture | B31: =D31&"."&E31&"-"&G31&"."&H31 | C31: =B31&"-"&J31&"-"&M31 | D31: AG | E31: MM | F31: =VLOOKUP(E31,'5.a Definitions'!E:F,2,FALSE) | G31: AG | H31: MM | I31: =VLOOKUP(H31,'5.a Definitions'!E:F,2,FALSE) | J31: Stock change | K31: =J31 | L31: reactive | M31: Nmix | N31: 1 | O31: 0.2 | P31: 2020 | Q31: text | R31: text | S31: text | T31: Germany | U31: - | V31: =(O31*N31)^2
B32: =D32&"."&E32&"-"&G32&"."&H32 | C32: =B32&"-"&J32&"-"&M32 | D32: AG | E32: SM | F32: =VLOOKUP(E32,'5.a Definitions'!E:F,2,FALSE) | G32: AG | H32: SM | I32: =VLOOKUP(H32,'5.a Definitions'!E:F,2,FALSE) | J32: Stock change | K32: =J32 | L32: reactive | M32: Nmix | N32: 1 | O32: 0.2 | P32: 2020 | Q32: text | R32: text | S32: text | T32: Germany | U32: - | V32: =(O32*N32)^2
B33: =D33&"."&E33&"-"&G33&"."&H33 | C33: =B33&"-"&J33&"-"&M33 | D33: AG | E33: BC | F33: =VLOOKUP(E33,'5.a Definitions'!E:F,2,FALSE) | G33: AG | H33: BC | I33: =VLOOKUP(H33,'5.a Definitions'!E:F,2,FALSE) | J33: Stock change | K33: =J33 | L33: reactive | M33: Nmix | N33: 1 | O33: 0.2 | P33: 2020 | Q33: text | R33: text | S33: text | T33: Germany | U33: - | V33: =(O33*N33)^2
A34: Forests and Semi-natural vegetation | B34: =D34&"."&E34&"-"&G34&"."&H34 | C34: =B34&"-"&J34&"-"&M34 | D34: FS | E34: FO | F34: =VLOOKUP(E34,'5.a Definitions'!E:F,2,FALSE) | G34: FS | H34: FO | I34: =VLOOKUP(H34,'5.a Definitions'!E:F,2,FALSE) | J34: Stock change | K34: =J34 | L34: reactive | M34: Nmix | N34: 1 | O34: 0.2 | P34: 2020 | Q34: text | R34: text | S34: text | T34: Germany | U34: - | V34: =(O34*N34)^2
B35: =D35&"."&E35&"-"&G35&"."&H35 | C35: =B35&"-"&J35&"-"&M35 | D35: FS | E35: OL | F35: =VLOOKUP(E35,'5.a Definitions'!E:F,2,FALSE) | G35: FS | H35: OL | I35: =VLOOKUP(H35,'5.a Definitions'!E:F,2,FALSE) | J35: Stock change | K35: =J35 | L35: reactive | M35: Nmix | N35: 1 | O35: 0.2 | P35: 2020 | Q35: text | R35: text | S35: text | T35: Germany | U35: - | V35: =(O35*N35)^2
B36: =D36&"."&E36&"-"&G36&"."&H36 | C36: =B36&"-"&J36&"-"&M36 | D36: FS | E36: WL | F36: =VLOOKUP(E36,'5.a Definitions'!E:F,2,FALSE) | G36: FS | H36: WL | I36: =VLOOKUP(H36,'5.a Definitions'!E:F,2,FALSE) | J36: Stock change | K36: =J36 | L36: reactive | M36: Nmix | N36: 1 | O36: 0.2 | P36: 2020 | Q36: text | R36: text | S36: text | T36: Germany | U36: - | V36: =(O36*N36)^2
A37: Processing of residues | B37: =D37&"."&E37&"-"&G37&"."&H37 | C37: =B37&"-"&J37&"-"&M37 | D37: PR | E37: SO | F37: =VLOOKUP(E37,'5.a Definitions'!E:F,2,FALSE) | G37: PR | H37: SO | I37: =VLOOKUP(H37,'5.a Definitions'!E:F,2,FALSE) | J37: Stock change | K37: =J37 | L37: reactive | M37: Nmix | N37: 1 | O37: 0.2 | P37: 2020 | Q37: text | R37: text | S37: text | T37: Germany | U37: - | V37: =(O37*N37)^2
B38: =D38&"."&E38&"-"&G38&"."&H38 | C38: =B38&"-"&J38&"-"&M38 | D38: PR | E38: WW | F38: =VLOOKUP(E38,'5.a Definitions'!E:F,2,FALSE) | G38: PR | H38: WW | I38: =VLOOKUP(H38,'5.a Definitions'!E:F,2,FALSE) | J38: Stock change | K38: =J38 | L38: reactive | M38: Nmix | N38: 1 | O38: 0.2 | P38: 2020 | Q38: text | R38: text | S38: text | T38: Germany | U38: - | V38: =(O38*N38)^2
A39: Humans and settlements | B39: =D39&"."&E39&"-"&G39&"."&H39 | C39: =B39&"-"&J39&"-"&M39 | D39: HS | E39: HS | F39: =VLOOKUP(E39,'5.a Definitions'!E:F,2,FALSE) | G39: HS | H39: HS | I39: =VLOOKUP(H39,'5.a Definitions'!E:F,2,FALSE) | J39: Stock change | K39: =J39 | L39: reactive | M39: Nmix | N39: 1 | O39: 0.2 | P39: 2020 | Q39: text | R39: text | S39: text | T39: Germany | U39: - | V39: =(O39*N39)^2
A40: Atmosphere | B40: =D40&"."&E40&"-"&G40&"."&H40 | C40: =B40&"-"&J40&"-"&M40 | D40: AT | E40: AT | F40: =VLOOKUP(E40,'5.a Definitions'!E:F,2,FALSE) | G40: AT | H40: AT | I40: =VLOOKUP(H40,'5.a Definitions'!E:F,2,FALSE) | J40: Stock change | K40: =J40 | L40: reactive | M40: Nmix | N40: 1 | O40: 0.2 | P40: 2020 | Q40: text | R40: text | S40: text | T40: Germany | U40: - | V40: =(O40*N40)^2
B41: =D41&"."&E41&"-"&G41&"."&H41 | C41: =B41&"-"&J41&"-"&M41 | D41: AT | E41: AT | F41: =VLOOKUP(E41,'5.a Definitions'!E:F,2,FALSE) | G41: AT | H41: AT | I41: =VLOOKUP(H41,'5.a Definitions'!E:F,2,FALSE) | J41: Stock change | K41: =J41 | L41: reactive | M41: Nmix | N41: 1 | O41: 0.2 | P41: 2020 | Q41: text | R41: text | S41: text | T41: Germany | U41: - | V41: =(O41*N41)^2
...

Sheet 3.1.a Input Output Matrix
A1: 3a Input and output matrix
A2: Data selection
A3: Year | B3: 2021
A4: N-Species | B4: Ntot
A6: Total inputs and outputs per pool in kt N
A7: The automatic color scheme of the background indicates high input-output values (dark green) and low input-output values (light green)
E9: Pool In
E10: EF | F10: MP | G10: AG | H10: FS | I10: PR | J10: HS | K10: HY | L10: AT | M10: RW | N10: Total kt N
C11: Pool Out | D11: EF | E11: =IF($B$4<>"Ntot",SUMIFS('2a. Database N flows'!$N:$N,'2a. Database N flows'!$D:$D,'3.1.a Input Output Matrix'!$D11,'2a. Database N flows'!$G:$G,'3.1.a Input Output Matrix'!E$10,'2a. Database N flows'!$P:$P,$B$3,'2a. Database N flows'!$M:$M,'3.1.a Input Output Matrix'!$B$4),SUMIFS('2a. Database N flows'!$N:$N,'2a. Database N flows'!$D:$D,'3.1.a Input Output Matrix'!$D11,'2a. Database N flows'!$G:$G,'3.1.a Input Output Matrix'!E$10,'2a. Database N flows'!$P:$P,$B$3)) | F11: =IF($B$4<>"Ntot",SUMIFS('2a. Database N flows'!$N:$N,'2a. Database N flows'!$D:$D,'3.1.a Input Output Matrix'!$D11,'2a. Database N flows'!$G:$G,'3.1.a Input Output Matrix'!F$10,'2a. Database N flows'!$P:$P,$B$3,'2a. Database N flows'!$M:$M,'3.1.a Input Output Matrix'!$B$4),SUMIFS('2a. Database N flows'!$N:$N,'2a. Database N flows'!$D:$D,'3.1.a Input Output Matrix'!$D11,'2a. Database N flows'!$G:$G,'3.1.a Input Output Matrix'!F$10,'2a. Database N flows'!$P:$P,$B$3)) | G11: =IF($B$4<>"Ntot",SUMIFS('2a. Database N flows'!$N:$N,'2a. Database N flows'!$D:$D,'3.1.a Input Output Matrix'!$D11,'2a. Database N flows'!$G:$G,'3.1.a Input Output Matrix'!G$10,'2a. Database N flows'!$P:$P,$B$3,'2a. Database N flows'!$M:$M,'3.1.a Input Output Matrix'!$B$4),SUMIFS('2a. Database N flows'!$N:$N,'2a. Database N flows'!$D:$D,'3.1.a Input Output Matrix'!$D11,'2a. Database N flows'!$G:$G,'3.1.a Input Output Matrix'!G$10,'2a. Database N flows'!$P:$P,$B$3)) | H11: =IF($B$4<>"Ntot",SUMIFS('2a. Database N flows'!$N:$N,'2a. Database N flows'!$D:$D,'3.1.a Input Output Matrix'!$D11,'2a. Database N flows'!$G:$G,'3.1.a Input Output Matrix'!H$10,'2a. Database N flows'!$P:$P,$B$3,'2a. Database N flows'!$M:$M,'3.1.a Input Output Matrix'!$B$4),SUMIFS('2a. Database N flows'!$N:$N,'2a. Database N flows'!$D:$D,'3.1.a Input Output Matrix'!$D11,'2a. Database N flows'!$G:$G,'3.1.a Input Output Matrix'!H$10,'2a. Database N flows'!$P:$P,$B$3)) | I11: =IF($B$4<>"Ntot",SUMIFS('2a. Database N flows'!$N:$N,'2a. Database N flows'!$D:$D,'3.1.a Input Output Matrix'!$D11,'2a. Database N flows'!$G:$G,'3.1.a Input Output Matrix'!I$10,'2a. Database N flows'!$P:$P,$B$3,'2a. Database N flows'!$M:$M,'3.1.a Input Output Matrix'!$B$4),SUMIFS('2a. Database N flows'!$N:$N,'2a. Database N flows'!$D:$D,'3.1.a Input Output Matrix'!$D11,'2a. Database N flows'!$G:$G,'3.1.a Input Output Matrix'!I$10,'2a. Database N flows'!$P:$P,$B$3)) | J11: =IF($B$4<>"Ntot",SUMIFS('2a. Database N flows'!$N:$N,'2a. Database N flows'!$D:$D,'3.1.a Input Output Matrix'!$D11,'2a. Database N flows'!$G:$G,'3.1.a Input Output Matrix'!J$10,'2a. Database N flows'!$P:$P,$B$3,'2a. Database N flows'!$M:$M,'3.1.a Input Output Matrix'!$B$4),SUMIFS('2a. Database N flows'!$N:$N,'2a. Database N flows'!$D:$D,'3.1.a Input Output Matrix'!$D11,'2a. Database N flows'!$G:$G,'3.1.a Input Output Matrix'!J$10,'2a. Database N flows'!$P:$P,$B$3)) | K11: =IF($B$4<>"Ntot",SUMIFS('2a. Database N flows'!$N:$N,'2a. Database N flows'!$D:$D,'3.1.a Input Output Matrix'!$D11,'2a. Database N flows'!$G:$G,'3.1.a Input Output Matrix'!K$10,'2a. Database N flows'!$P:$P,$B$3,'2a. Database N flows'!$M:$M,'3.1.a Input Output Matrix'!$B$4),SUMIFS('2a. Database N flows'!$N:$N,'2a. Database N flows'!$D:$D,'3.1.a Input Output Matrix'!$D11,'2a. Database N flows'!$G:$G,'3.1.a Input Output Matrix'!K$10,'2a. Database N flows'!$P:$P,$B$3)) | L11: =IF($B$4<>"Ntot",SUMIFS('2a. Database N flows'!$N:$N,'2a. Database N flows'!$D:$D,'3.1.a Input Output Matrix'!$D11,'2a. Database N flows'!$G:$G,'3.1.a Input Output Matrix'!L$10,'2a. Database N flows'!$P:$P,$B$3,'2a. Database N flows'!$M:$M,'3.1.a Input Output Matrix'!$B$4),SUMIFS('2a. Database N flows'!$N:$N,'2a. Database N flows'!$D:$D,'3.1.a Input Output Matrix'!$D11,'2a. Database N flows'!$G:$G,'3.1.a Input Output Matrix'!L$10,'2a. Database N flows'!$P:$P,$B$3)) | M11: =IF($B$4<>"Ntot",SUMIFS('2a. Database N flows'!$N:$N,'2a. Database N flows'!$D:$D,'3.1.a Input Output Matrix'!$D11,'2a. Database N flows'!$G:$G,'3.1.a Input Output Matrix'!M$10,'2a. Database N flows'!$P:$P,$B$3,'2a. Database N flows'!$M:$M,'3.1.a Input Output Matrix'!$B$4),SUMIFS('2a. Database N flows'!$N:$N,'2a. Database N flows'!$D:$D,'3.1.a Input Output Matrix'!$D11,'2a. Database N flows'!$G:$G,'3.1.a Input Output Matrix'!M$10,'2a. Database N flows'!$P:$P,$B$3)) | N11: =SUM(E11:M11) | O11: kt N
D12: MP | E12: =IF($B$4<>"Ntot",SUMIFS('2a. Database N flows'!$N:$N,'2a. Database N flows'!$D:$D,'3.1.a Input Output Matrix'!$D12,'2a. Database N flows'!$G:$G,'3.1.a Input Output Matrix'!E$10,'2a. Database N flows'!$P:$P,$B$3,'2a. Database N flows'!$M:$M,'3.1.a Input Output Matrix'!$B$4),SUMIFS('2a. Database N flows'!$N:$N,'2a. Database N flows'!$D:$D,'3.1.a Input Output Matrix'!$D12,'2a. Database N flows'!$G:$G,'3.1.a Input Output Matrix'!E$10,'2a. Database N flows'!$P:$P,$B$3)) | F12: =IF($B$4<>"Ntot",SUMIFS('2a. Database N flows'!$N:$N,'2a. Database N flows'!$D:$D,'3.1.a Input Output Matrix'!$D12,'2a. Database N flows'!$G:$G,'3.1.a Input Output Matrix'!F$10,'2a. Database N flows'!$P:$P,$B$3,'2a. Database N flows'!$M:$M,'3.1.a Input Output Matrix'!$B$4),SUMIFS('2a. Database N flows'!$N:$N,'2a. Database N flows'!$D:$D,'3.1.a Input Output Matrix'!$D12,'2a. Database N flows'!$G:$G,'3.1.a Input Output Matrix'!F$10,'2a. Database N flows'!$P:$P,$B$3)) | G12: =IF($B$4<>"Ntot",SUMIFS('2a. Database N flows'!$N:$N,'2a. Database N flows'!$D:$D,'3.1.a Input Output Matrix'!$D12,'2a. Database N flows'!$G:$G,'3.1.a Input Output Matrix'!G$10,'2a. Database N flows'!$P:$P,$B$3,'2a. Database N flows'!$M:$M,'3.1.a Input Output Matrix'!$B$4),SUMIFS('2a. Database N flows'!$N:$N,'2a. Database N flows'!$D:$D,'3.1.a Input Output Matrix'!$D12,'2a. Database N flows'!$G:$G,'3.1.a Input Output Matrix'!G$10,'2a. Database N flows'!$P:$P,$B$3)) | H12: =IF($B$4<>"Ntot",SUMIFS('2a. Database N flows'!$N:$N,'2a. Database N flows'!$D:$D,'3.1.a Input Output Matrix'!$D12,'2a. Database N flows'!$G:$G,'3.1.a Input Output Matrix'!H$10,'2a. Database N flows'!$P:$P,$B$3,'2a. Database N flows'!$M:$M,'3.1.a Input Output Matrix'!$B$4),SUMIFS('2a. Database N flows'!$N:$N,'2a. Database N flows'!$D:$D,'3.1.a Input Output Matrix'!$D12,'2a. Database N flows'!$G:$G,'3.1.a Input Output Matrix'!H$10,'2a. Database N flows'!$P:$P,$B$3)) | I12: =IF($B$4<>"Ntot",SUMIFS('2a. Database N flows'!$N:$N,'2a. Database N flows'!$D:$D,'3.1.a Input Output Matrix'!$D12,'2a. Database N flows'!$G:$G,'3.1.a Input Output Matrix'!I$10,'2a. Database N flows'!$P:$P,$B$3,'2a. Database N flows'!$M:$M,'3.1.a Input Output Matrix'!$B$4),SUMIFS('2a. Database N flows'!$N:$N,'2a. Database N flows'!$D:$D,'3.1.a Input Output Matrix'!$D12,'2a. Database N flows'!$G:$G,'3.1.a Input Output Matrix'!I$10,'2a. Database N flows'!$P:$P,$B$3)) | J12: =IF($B$4<>"Ntot",SUMIFS('2a. Database N flows'!$N:$N,'2a. Database N flows'!$D:$D,'3.1.a Input Output Matrix'!$D12,'2a. Database N flows'!$G:$G,'3.1.a Input Output Matrix'!J$10,'2a. Database N flows'!$P:$P,$B$3,'2a. Database N flows'!$M:$M,'3.1.a Input Output Matrix'!$B$4),SUMIFS('2a. Database N flows'!$N:$N,'2a. Database N flows'!$D:$D,'3.1.a Input Output Matrix'!$D12,'2a. Database N flows'!$G:$G,'3.1.a Input Output Matrix'!J$10,'2a. Database N flows'!$P:$P,$B$3)) | K12: =IF($B$4<>"Ntot",SUMIFS('2a. Database N flows'!$N:$N,'2a. Database N flows'!$D:$D,'3.1.a Input Output Matrix'!$D12,'2a. Database N flows'!$G:$G,'3.1.a Input Output Matrix'!K$10,'2a. Database N flows'!$P:$P,$B$3,'2a. Database N flows'!$M:$M,'3.1.a Input Output Matrix'!$B$4),SUMIFS('2a. Database N flows'!$N:$N,'2a. Database N flows'!$D:$D,'3.1.a Input Output Matrix'!$D12,'2a. Database N flows'!$G:$G,'3.1.a Input Output Matrix'!K$10,'2a. Database N flows'!$P:$P,$B$3)) | L12: =IF($B$4<>"Ntot",SUMIFS('2a. Database N flows'!$N:$N,'2a. Database N flows'!$D:$D,'3.1.a Input Output Matrix'!$D12,'2a. Database N flows'!$G:$G,'3.1.a Input Output Matrix'!L$10,'2a. Database N flows'!$P:$P,$B$3,'2a. Database N flows'!$M:$M,'3.1.a Input Output Matrix'!$B$4),SUMIFS('2a. Database N flows'!$N:$N,'2a. Database N flows'!$D:$D,'3.1.a Input Output Matrix'!$D12,'2a. Database N flows'!$G:$G,'3.1.a Input Output Matrix'!L$10,'2a. Database N flows'!$P:$P,$B$3)) | M12: =IF($B$4<>"Ntot",SUMIFS('2a. Database N flows'!$N:$N,'2a. Database N flows'!$D:$D,'3.1.a Input Output Matrix'!$D12,'2a. Database N flows'!$G:$G,'3.1.a Input Output Matrix'!M$10,'2a. Database N flows'!$P:$P,$B$3,'2a. Database N flows'!$M:$M,'3.1.a Input Output Matrix'!$B$4),SUMIFS('2a. Database N flows'!$N:$N,'2a. Database N flows'!$D:$D,'3.1.a Input Output Matrix'!$D12,'2a. Database N flows'!$G:$G,'3.1.a Input Output Matrix'!M$10,'2a. Database N flows'!$P:$P,$B$3)) | N12: =SUM(E12:M12) | O12: kt N
D13: AG | E13: =IF($B$4<>"Ntot",SUMIFS('2a. Database N flows'!$N:$N,'2a. Database N flows'!$D:$D,'3.1.a Input Output Matrix'!$D13,'2a. Database N flows'!$G:$G,'3.1.a Input Output Matrix'!E$10,'2a. Database N flows'!$P:$P,$B$3,'2a. Database N flows'!$M:$M,'3.1.a Input Output Matrix'!$B$4),SUMIFS('2a. Database N flows'!$N:$N,'2a. Database N flows'!$D:$D,'3.1.a Input Output Matrix'!$D13,'2a. Database N flows'!$G:$G,'3.1.a Input Output Matrix'!E$10,'2a. Database N flows'!$P:$P,$B$3)) | F13: =IF($B$4<>"Ntot",SUMIFS('2a. Database N flows'!$N:$N,'2a. Database N flows'!$D:$D,'3.1.a Input Output Matrix'!$D13,'2a. Database N flows'!$G:$G,'3.1.a Input Output Matrix'!F$10,'2a. Database N flows'!$P:$P,$B$3,'2a. Database N flows'!$M:$M,'3.1.a Input Output Matrix'!$B$4),SUMIFS('2a. Database N flows'!$N:$N,'2a. Database N flows'!$D:$D,'3.1.a Input Output Matrix'!$D13,'2a. Database N flows'!$G:$G,'3.1.a Input Output Matrix'!F$10,'2a. Database N flows'!$P:$P,$B$3)) | G13: =IF($B$4<>"Ntot",SUMIFS('2a. Database N flows'!$N:$N,'2a. Database N flows'!$D:$D,'3.1.a Input Output Matrix'!$D13,'2a. Database N flows'!$G:$G,'3.1.a Input Output Matrix'!G$10,'2a. Database N flows'!$P:$P,$B$3,'2a. Database N flows'!$M:$M,'3.1.a Input Output Matrix'!$B$4),SUMIFS('2a. Database N flows'!$N:$N,'2a. Database N flows'!$D:$D,'3.1.a Input Output Matrix'!$D13,'2a. Database N flows'!$G:$G,'3.1.a Input Output Matrix'!G$10,'2a. Database N flows'!$P:$P,$B$3)) | H13: =IF($B$4<>"Ntot",SUMIFS('2a. Database N flows'!$N:$N,'2a. Database N flows'!$D:$D,'3.1.a Input Output Matrix'!$D13,'2a. Database N flows'!$G:$G,'3.1.a Input Output Matrix'!H$10,'2a. Database N flows'!$P:$P,$B$3,'2a. Database N flows'!$M:$M,'3.1.a Input Output Matrix'!$B$4),SUMIFS('2a. Database N flows'!$N:$N,'2a. Database N flows'!$D:$D,'3.1.a Input Output Matrix'!$D13,'2a. Database N flows'!$G:$G,'3.1.a Input Output Matrix'!H$10,'2a. Database N flows'!$P:$P,$B$3)) | I13: =IF($B$4<>"Ntot",SUMIFS('2a. Database N flows'!$N:$N,'2a. Database N flows'!$D:$D,'3.1.a Input Output Matrix'!$D13,'2a. Database N flows'!$G:$G,'3.1.a Input Output Matrix'!I$10,'2a. Database N flows'!$P:$P,$B$3,'2a. Database N flows'!$M:$M,'3.1.a Input Output Matrix'!$B$4),SUMIFS('2a. Database N flows'!$N:$N,'2a. Database N flows'!$D:$D,'3.1.a Input Output Matrix'!$D13,'2a. Database N flows'!$G:$G,'3.1.a Input Output Matrix'!I$10,'2a. Database N flows'!$P:$P,$B$3)) | J13: =IF($B$4<>"Ntot",SUMIFS('2a. Database N flows'!$N:$N,'2a. Database N flows'!$D:$D,'3.1.a Input Output Matrix'!$D13,'2a. Database N flows'!$G:$G,'3.1.a Input Output Matrix'!J$10,'2a. Database N flows'!$P:$P,$B$3,'2a. Database N flows'!$M:$M,'3.1.a Input Output Matrix'!$B$4),SUMIFS('2a. Database N flows'!$N:$N,'2a. Database N flows'!$D:$D,'3.1.a Input Output Matrix'!$D13,'2a. Database N flows'!$G:$G,'3.1.a Input Output Matrix'!J$10,'2a. Database N flows'!$P:$P,$B$3)) | K13: =IF($B$4<>"Ntot",SUMIFS('2a. Database N flows'!$N:$N,'2a. Database N flows'!$D:$D,'3.1.a Input Output Matrix'!$D13,'2a. Database N flows'!$G:$G,'3.1.a Input Output Matrix'!K$10,'2a. Database N flows'!$P:$P,$B$3,'2a. Database N flows'!$M:$M,'3.1.a Input Output Matrix'!$B$4),SUMIFS('2a. Database N flows'!$N:$N,'2a. Database N flows'!$D:$D,'3.1.a Input Output Matrix'!$D13,'2a. Database N flows'!$G:$G,'3.1.a Input Output Matrix'!K$10,'2a. Database N flows'!$P:$P,$B$3)) | L13: =IF($B$4<>"Ntot",SUMIFS('2a. Database N flows'!$N:$N,'2a. Database N flows'!$D:$D,'3.1.a Input Output Matrix'!$D13,'2a. Database N flows'!$G:$G,'3.1.a Input Output Matrix'!L$10,'2a. Database N flows'!$P:$P,$B$3,'2a. Database N flows'!$M:$M,'3.1.a Input Output Matrix'!$B$4),SUMIFS('2a. Database N flows'!$N:$N,'2a. Database N flows'!$D:$D,'3.1.a Input Output Matrix'!$D13,'2a. Database N flows'!$G:$G,'3.1.a Input Output Matrix'!L$10,'2a. Database N flows'!$P:$P,$B$3)) | M13: =IF($B$4<>"Ntot",SUMIFS('2a. Database N flows'!$N:$N,'2a. Database N flows'!$D:$D,'3.1.a Input Output Matrix'!$D13,'2a. Database N flows'!$G:$G,'3.1.a Input Output Matrix'!M$10,'2a. Database N flows'!$P:$P,$B$3,'2a. Database N flows'!$M:$M,'3.1.a Input Output Matrix'!$B$4),SUMIFS('2a. Database N flows'!$N:$N,'2a. Database N flows'!$D:$D,'3.1.a Input Output Matrix'!$D13,'2a. Database N flows'!$G:$G,'3.1.a Input Output Matrix'!M$10,'2a. Database N flows'!$P:$P,$B$3)) | N13: =SUM(E13:M13) | O13: kt N
D14: FS | E14: =IF($B$4<>"Ntot",SUMIFS('2a. Database N flows'!$N:$N,'2a. Database N flows'!$D:$D,'3.1.a Input Output Matrix'!$D14,'2a. Database N flows'!$G:$G,'3.1.a Input Output Matrix'!E$10,'2a. Database N flows'!$P:$P,$B$3,'2a. Database N flows'!$M:$M,'3.1.a Input Output Matrix'!$B$4),SUMIFS('2a. Database N flows'!$N:$N,'2a. Database N flows'!$D:$D,'3.1.a Input Output Matrix'!$D14,'2a. Database N flows'!$G:$G,'3.1.a Input Output Matrix'!E$10,'2a. Database N flows'!$P:$P,$B$3)) | F14: =IF($B$4<>"Ntot",SUMIFS('2a. Database N flows'!$N:$N,'2a. Database N flows'!$D:$D,'3.1.a Input Output Matrix'!$D14,'2a. Database N flows'!$G:$G,'3.1.a Input Output Matrix'!F$10,'2a. Database N flows'!$P:$P,$B$3,'2a. Database N flows'!$M:$M,'3.1.a Input Output Matrix'!$B$4),SUMIFS('2a. Database N flows'!$N:$N,'2a. Database N flows'!$D:$D,'3.1.a Input Output Matrix'!$D14,'2a. Database N flows'!$G:$G,'3.1.a Input Output Matrix'!F$10,'2a. Database N flows'!$P:$P,$B$3)) | G14: =IF($B$4<>"Ntot",SUMIFS('2a. Database N flows'!$N:$N,'2a. Database N flows'!$D:$D,'3.1.a Input Output Matrix'!$D14,'2a. Database N flows'!$G:$G,'3.1.a Input Output Matrix'!G$10,'2a. Database N flows'!$P:$P,$B$3,'2a. Database N flows'!$M:$M,'3.1.a Input Output Matrix'!$B$4),SUMIFS('2a. Database N flows'!$N:$N,'2a. Database N flows'!$D:$D,'3.1.a Input Output Matrix'!$D14,'2a. Database N flows'!$G:$G,'3.1.a Input Output Matrix'!G$10,'2a. Database N flows'!$P:$P,$B$3)) | H14: =IF($B$4<>"Ntot",SUMIFS('2a. Database N flows'!$N:$N,'2a. Database N flows'!$D:$D,'3.1.a Input Output Matrix'!$D14,'2a. Database N flows'!$G:$G,'3.1.a Input Output Matrix'!H$10,'2a. Database N flows'!$P:$P,$B$3,'2a. Database N flows'!$M:$M,'3.1.a Input Output Matrix'!$B$4),SUMIFS('2a. Database N flows'!$N:$N,'2a. Database N flows'!$D:$D,'3.1.a Input Output Matrix'!$D14,'2a. Database N flows'!$G:$G,'3.1.a Input Output Matrix'!H$10,'2a. Database N flows'!$P:$P,$B$3)) | I14: =IF($B$4<>"Ntot",SUMIFS('2a. Database N flows'!$N:$N,'2a. Database N flows'!$D:$D,'3.1.a Input Output Matrix'!$D14,'2a. Database N flows'!$G:$G,'3.1.a Input Output Matrix'!I$10,'2a. Database N flows'!$P:$P,$B$3,'2a. Database N flows'!$M:$M,'3.1.a Input Output Matrix'!$B$4),SUMIFS('2a. Database N flows'!$N:$N,'2a. Database N flows'!$D:$D,'3.1.a Input Output Matrix'!$D14,'2a. Database N flows'!$G:$G,'3.1.a Input Output Matrix'!I$10,'2a. Database N flows'!$P:$P,$B$3)) | J14: =IF($B$4<>"Ntot",SUMIFS('2a. Database N flows'!$N:$N,'2a. Database N flows'!$D:$D,'3.1.a Input Output Matrix'!$D14,'2a. Database N flows'!$G:$G,'3.1.a Input Output Matrix'!J$10,'2a. Database N flows'!$P:$P,$B$3,'2a. Database N flows'!$M:$M,'3.1.a Input Output Matrix'!$B$4),SUMIFS('2a. Database N flows'!$N:$N,'2a. Database N flows'!$D:$D,'3.1.a Input Output Matrix'!$D14,'2a. Database N flows'!$G:$G,'3.1.a Input Output Matrix'!J$10,'2a. Database N flows'!$P:$P,$B$3)) | K14: =IF($B$4<>"Ntot",SUMIFS('2a. Database N flows'!$N:$N,'2a. Database N flows'!$D:$D,'3.1.a Input Output Matrix'!$D14,'2a. Database N flows'!$G:$G,'3.1.a Input Output Matrix'!K$10,'2a. Database N flows'!$P:$P,$B$3,'2a. Database N flows'!$M:$M,'3.1.a Input Output Matrix'!$B$4),SUMIFS('2a. Database N flows'!$N:$N,'2a. Database N flows'!$D:$D,'3.1.a Input Output Matrix'!$D14,'2a. Database N flows'!$G:$G,'3.1.a Input Output Matrix'!K$10,'2a. Database N flows'!$P:$P,$B$3)) | L14: =IF($B$4<>"Ntot",SUMIFS('2a. Database N flows'!$N:$N,'2a. Database N flows'!$D:$D,'3.1.a Input Output Matrix'!$D14,'2a. Database N flows'!$G:$G,'3.1.a Input Output Matrix'!L$10,'2a. Database N flows'!$P:$P,$B$3,'2a. Database N flows'!$M:$M,'3.1.a Input Output Matrix'!$B$4),SUMIFS('2a. Database N flows'!$N:$N,'2a. Database N flows'!$D:$D,'3.1.a Input Output Matrix'!$D14,'2a. Database N flows'!$G:$G,'3.1.a Input Output Matrix'!L$10,'2a. Database N flows'!$P:$P,$B$3)) | M14: =IF($B$4<>"Ntot",SUMIFS('2a. Database N flows'!$N:$N,'2a. Database N flows'!$D:$D,'3.1.a Input Output Matrix'!$D14,'2a. Database N flows'!$G:$G,'3.1.a Input Output Matrix'!M$10,'2a. Database N flows'!$P:$P,$B$3,'2a. Database N flows'!$M:$M,'3.1.a Input Output Matrix'!$B$4),SUMIFS('2a. Database N flows'!$N:$N,'2a. Database N flows'!$D:$D,'3.1.a Input Output Matrix'!$D14,'2a. Database N flows'!$G:$G,'3.1.a Input Output Matrix'!M$10,'2a. Database N flows'!$P:$P,$B$3)) | N14: =SUM(E14:M14) | O14: kt N
